Workbook

Sheet Summary
D1: RawData | E1: Distinct | F1: Duplicates
B2: Total Rows | D2: =ROWS(RawData!A2:A4130) -> 4129 | E2: =ROWS(Distinct!A2:A3528) -> 3527 | F2: =ROWS(Duplicates!A2:A1131) -> 1130
B3: Row Counts(with Score) | D3: =COUNTIF(RawData!E2:E4130,"<>") -> 3985 | E3: =COUNTIF(Distinct!E2:E4130,"<>") -> 3399 | F3: =COUNTIF(Duplicates!E2:E4130,"<>") -> 1103
B5: Data Types:
B6: Submission ID | D6: String
B7: Respondent ID | D7: String
B8: Submitted at | D8: Date
B9: Loan Id | D9: String
B10: Using a scale from 0 (not likely) to 10 (very likely), how likely are you to recommend ABC Phones to friends or family? | D10: Integer
B11: What is the main reason for your score? | D11: String
B12: What is one thing we could do to improve your experience with us? | D12: String
B13: Are you happy with the quality and performance of your device? | D13: String
B14: Are you happy with the service and support provided by ABC Phones? | D14: String

Sheet RawData
A1: Submission ID | B1: Respondent ID | C1: Submitted at | D1: Loan Id | E1: Using a scale from 0 (not likely) to 10 (very likely), how likely are you to recommend ABC Phones to friends or family? | F1: What is the main reason for your score? | G1: What is one thing we could do to improve your experience with us? | H1: Are you happy with the quality and performance of your device? | I1: Are you happy with the service and support provided by ABC Phones? | J1: Have you ever experienced a delay in your payment reflecting in your ABC account? | K1: Have you ever had difficulty getting assistance from ABC Phones customer support when needed? | L1: (If Yes) – Please describe the challenge you faced and how we can improve your experience. | M1: Have you experienced any battery-related issues with your MoPhones device? | N1: Have you used the MoPhones app (MoApp) to manage your account or make payments? | O1: Which communication channel do you prefer when contacting MoPhones for inquiries or support? | P1: Have you ever had your phone lock despite making a payment on time? | Q1: Any other Feedback?
A2: BzK4Q11 | B2: k4z1Y6 | C2: 45769.635 | D2: rec2FCxHhqXw6aKRU | E2: 6 | H2: Yes | I2: Yes | J2: Yes | K2: Yes | L2: Unlocking my phone | M2: No | N2: Yes, and I am satisfied with the MoApp | O2: MoPhones App | P2: Yes | Q2: N/A
A3: b59V45Z | B3: AY9GMk | C3: 45769.637 | D3: recQcLWbPcep18Wdw | E3: 10 | H3: Yes | I3: Yes | J3: No | K3: No | L3: Response team always on time | M3: No | N3: Yes, and I am satisfied with the MoApp | O3: Free SMS – 25044 | P3: No | Q3: Would like to upgrade once I'm done with this loan
A4: GxKvYKO | B4: eGz8Ek | C4: 45769.647 | D4: recei9UEU0e5F9HuG | E4: 5 | H4: No | I4: No | J4: No | K4: Yes | L4: I bought a Samsung A42 which has fingerprint lock that doesn't work since I bought it from ABC, I took it back and it's wasn't fixed.. Then the Phone has an on and Off network issues | M4: No | N4: Yes, and I am satisfied with the MoApp | O4: Phone Call – +254 728 444 442 or +254 709 924 404 | P4: Yes | Q4: Good service and efficient response
A5: A7KP49z | B5: LjOx7j | C5: 45769.653 | D5: recosDWAJvWzAKgLv | E5: 1 | H5: No | I5: No | J5: Yes | K5: Yes | L5: Delays | M5: Yes | N5: Yes, but I am not satisfied with the MoApp
A6: 81zo6pr | B6: 7YE0RR | C6: 45769.653 | D6: recTJng0Mj0dJP1kv | E6: 1 | H6: No | I6: No | J6: Yes | K6: Yes | L6: Not satisfied with my phone | M6: Yes | N6: Yes, but I am not satisfied with the MoApp | O6: MoPhones App | P6: Yes | Q6: Not satisfied with my phone
A7: xXjxR5J | B7: RQjeLp | C7: 45769.653 | D7: recPKFOtpkS0z9Kpp | E7: 10 | H7: Yes | I7: Yes | J7: No | K7: No | L7: . | M7: No | N7: Yes, and I am satisfied with the MoApp | O7: Phone Call – +254 728 444 442 or +254 709 924 404 | P7: No | Q7: .
A8: GxKvQ6L | B8: ljz2Mo | C8: 45769.653 | D8: rechy4Nf0Ihxrdy85 | E8: 10
A9: rjBykB2 | B9: k4zjvo | C9: 45769.654 | D9: recayIesPKGAMilkX | E9: 0
A10: 5B4KeaM | B10: k4zjZJ | C10: 45769.654 | D10: rec86PnPzgTEunR4Q | E10: 9 | H10: No | I10: No | J10: Yes | K10: Yes | L10: There is a lot to be | M10: No | N10: Yes, and I am satisfied with the MoApp | O10: MoPhones App | P10: Yes | Q10: None
A11: 5B4Kp16 | B11: rQY9pN | C11: 45769.656 | D11: recJKsUBTzHl4IGK3 | E11: 10 | H11: Yes | I11: Yes | J11: Yes | K11: No, I have never looked for customer care | L11: N/A | M11: No | N11: Yes, and I am satisfied with the MoApp | O11: Phone Call – +254 728 444 442 or +254 709 924 404 | P11: No | Q11: N/A
A12: eqDZYBO | B12: AY9RGD | C12: 45769.656 | D12: recUmt3DbYL0gb025 | E12: 10 | H12: Yes | I12: Yes | J12: No | K12: No | L12: None | M12: No | N12: Yes, and I am satisfied with the MoApp | O12: Reach Out via a Sales Agent | P12: No | Q12: None
A13: aQeNaYv | B13: yRD5Dg | C13: 45769.656 | D13: recVOllpG6mFoGtaV | E13: 8 | H13: No | I13: Yes | J13: No | K13: No | L13: Battery can't store charge I need a replaced of battery | M13: Yes | N13: Yes, and I am satisfied with the MoApp | O13: Phone Call – +254 728 444 442 or +254 709 924 404 | P13: No | Q13: Kindly exchange my battery
A14: dWNqK2d | B14: gVzV5M | C14: 45769.656 | D14: reciMIpVjO2lBzHt8 | E14: 7 | H14: Yes | I14: Yes | J14: Yes | K14: No | L14: Payment terms are harsh | M14: No | N14: No, I have never used it | O14: Phone Call – +254 728 444 442 or +254 709 924 404 | P14: Yes | Q14: You need to check on payment terms
A15: WOr9jYJ | B15: AY9RN0 | C15: 45769.656 | D15: receJwqtM49LS8gE8 | E15: 10 | H15: Yes | I15: Yes | J15: Yes | K15: No, I have never looked for customer care | L15: No | M15: No | N15: No, I have never used it | O15: Phone Call – +254 728 444 442 or +254 709 924 404 | P15: Yes | Q15: Am happy for your service
A16: zxNX1Q8 | B16: 4YO00O | C16: 45769.656 | D16: recB2N3ejw9jeBo4l | E16: 0 | H16: No | I16: No | J16: Yes | K16: Yes | L16: My phone is not working despite payment | M16: Yes | N16: Yes, and I am satisfied with the MoApp | O16: Phone Call – +254 728 444 442 or +254 709 924 404 | P16: Yes | Q16: My phone has a charging problem since
A17: jabDkpQ | B17: gVzPBK | C17: 45769.657 | D17: recK9QseqaimraXBE | E17: 8 | H17: Yes | I17: Yes | J17: Yes | K17: No | L17: Have a 24/7 customer care services | M17: Yes | N17: Yes, but I am not satisfied with the MoApp | O17: Phone Call – +254 728 444 442 or +254 709 924 404 | P17: No | Q17: No
A18: PdDjkDx | B18: gVz85l | C18: 45769.658 | D18: rectavMBbkg1rwXIl | E18: 10 | H18: Yes | I18: Yes | J18: No | K18: No
A19: MeDK74X | B19: 8YrbNl | C19: 45769.659 | D19: recu8gML0JT6Cd9ES | E19: 3 | H19: No | I19: No | J19: Yes | K19: Yes | M19: Yes | N19: Yes, but I am not satisfied with the MoApp | O19: MoPhones App | P19: No | Q19: Improve in your app
A20: vGrjKyl | B20: 4YOlvb | C20: 45769.659 | D20: recHDnVDRlfvts5dQ | E20: 6 | H20: Yes | I20: Yes | J20: No | K20: Yes | L20: MOPHONES | M20: Yes | N20: Yes, and I am satisfied with the MoApp | O20: Free SMS – 25044 | P20: No | Q20: Nome
A21: XxrlzDL | B21: Qq4NYg | C21: 45769.66 | D21: recvDdpWZLA2VCChR | E21: 10 | H21: Yes | I21: No | J21: No | K21: Yes | L21: Support center should work 24\7 | M21: No | N21: No, I have never used it | O21: Phone Call – +254 728 444 442 or +254 709 924 404 | P21: Yes | Q21: No
A22: zxNXL0q | B22: AY9M4N | C22: 45769.66 | D22: rec7AnOdegQgCwyT6 | E22: 8 | H22: Yes | I22: Yes | J22: Yes | K22: No | L22: Avoid delay while approving a grace period | M22: Yes | N22: Yes, and I am satisfied with the MoApp | O22: Free SMS – 25044 | P22: Yes | Q22: None
A23: Y5RDkx6 | B23: k4z8rZ | C23: 45769.66 | D23: recIZZtnG0LN1MpqF | E23: 9 | H23: Yes | I23: Yes | J23: Yes | K23: Yes | L23: You don't accept calls
A24: 7RblMyZ | B24: ljz8GB | C24: 45769.66 | D24: recAyJ8v8VJuecwtB | E24: 9 | H24: Yes | I24: Yes | J24: No | K24: No
A25: kd9av2R | B25: OZEx27 | C25: 45769.661 | D25: recjPY1G5I3fQxMOn | E25: 8 | H25: Yes | I25: Yes | J25: No | K25: No | L25: Non | M25: No | N25: Yes, but I am not satisfied with the MoApp | O25: Free SMS – 25044 | P25: No | Q25: No
A26: 2EB87Zg | B26: dozJVr | C26: 45769.662 | D26: rec4fZqbuemGwnwZF | E26: 10 | H26: Yes | I26: Yes | J26: No | K26: No | L26: No | M26: Yes | N26: No, I have never used it | O26: Phone Call – +254 728 444 442 or +254 709 924 404 | P26: No | Q26: No
A27: MeDKVb8 | B27: Jrovpz | C27: 45769.662 | D27: recl4egRn2rQH4mO0 | H27: Yes | I27: Yes
A28: Y5RD9G0 | B28: Jrov97 | C28: 45769.662 | D28: recQJWCGAZ7yuy0k7 | E28: 8 | H28: Yes | I28: Yes | J28: Yes | K28: No | L28: No
A29: 9qXG4Z4 | B29: GVbAez | C29: 45769.662 | D29: rec6r5JWy61FR24fB | E29: 9 | H29: Yes | I29: Yes | J29: No | K29: No
A30: xXjxvbv | B30: RQjqej | C30: 45769.662 | D30: recEx6e0qdGKb242p | E30: 10 | H30: Yes | I30: Yes | J30: No | K30: No | L30: No | M30: Yes | N30: Yes, and I am satisfied with the MoApp | O30: MoPhones App | P30: No | Q30: Had some challenges at the beginning but they were sorted.The only big problem I have with device is about battery.It doesn't last even 3 hours after full charge.
A31: Ek5z6ao | B31: 6YPEOk | C31: 45769.663 | D31: recCz1heG9HYapz1Z | E31: 10 | H31: Yes | I31: Yes | J31: Yes
A32: GxKvb5p | B32: JrovLR | C32: 45769.664 | D32: recqipYF4bAylKqe7 | E32: 6 | H32: Yes | I32: Yes | J32: No | K32: No, I have never looked for customer care | L32: 0 | M32: No | N32: Yes, and I am satisfied with the MoApp | O32: MoPhones App | P32: Yes | Q32: 0
A33: J9dKoXo | B33: 2YoGkD | C33: 45769.665 | D33: recbprJ3ndI6F0BhS | E33: 7 | H33: No | I33: Yes | J33: Yes | K33: Yes | L33: Someday I texted WhatsApp | M33: Yes | N33: Yes, and I am satisfied with the MoApp | O33: Reach Out via a Sales Agent | P33: No | Q33: NA
A34: yPNZ1pW | B34: gVz6Yd | C34: 45769.665 | D34: recO4cc15FMgzK9Jf | E34: 5 | H34: Yes | I34: No | J34: Yes | K34: Yes | L34: Weekends | M34: No | N34: No, I have never used it | O34: Reach Out via a Sales Agent | P34: Yes | Q34: Weekend
A35: jabDvGE | B35: NxP2RN | C35: 45769.665 | D35: recz6bPleTRitJUVS | E35: 3 | H35: Yes | I35: No | J35: Yes | K35: Yes | L35: I came to your shop with a complain about the phone battery bt bt instead of charging it, they gave me back the phone with the problem | M35: Yes | N35: No, I have never used it | O35: Phone Call – +254 728 444 442 or +254 709 924 404 | P35: Yes | Q35: No
A36: VLjENej | B36: gVz6z1 | C36: 45769.666 | D36: receqs5xvBzt3P9sN | E36: 8 | H36: Yes | I36: Yes | J36: No | K36: No | L36: have always been satisfied. | M36: No | N36: Yes, and I am satisfied with the MoApp | O36: Phone Call – +254 728 444 442 or +254 709 924 404 | P36: Yes | Q36: despite the challenge have had, am equally satisfied with your services.
A37: LZz1OB2 | B37: qqz1o7 | C37: 45769.666 | D37: rec9xhHoNXXxZVhm1 | E37: 6 | H37: Yes | I37: Yes | J37: No | K37: No | L37: T | M37: Yes | N37: Yes, but I am not satisfied with the MoApp | O37: Phone Call – +254 728 444 442 or +254 709 924 404 | P37: No | Q37: The MoApp should show the history of all transactions relating to a device payment.
A38: pbdxZrq | B38: BYeWY1 | C38: 45769.666 | D38: rect7DnuaYY5R6mKZ | E38: 8 | H38: Yes | I38: Yes | J38: No | K38: No | L38: I love ur phones | M38: No | N38: Yes, and I am satisfied with the MoApp | O38: Phone Call – +254 728 444 442 or +254 709 924 404 | P38: No | Q38: Goodservices viva!!
A39: Zjo5QEy | B39: 6YPE0A | C39: 45769.667 | D39: recLaXBaXTBTK6jWH | E39: 10 | H39: Yes | I39: Yes | J39: No | K39: No | L39: 😁 | M39: No | N39: No, I have never used it | O39: Phone Call – +254 728 444 442 or +254 709 924 404 | P39: Yes | Q39: 😎😮‍💨
A40: yPNZ71x | B40: 7YEkqL | C40: 45769.667 | D40: recJKLuwWfZr7TL15 | E40: 8 | H40: Yes | I40: Yes
...

Sheet Distinct
A1: Submission ID | B1: Respondent ID | C1: Submitted at | D1: Loan Id | E1: Using a scale from 0 (not likely) to 10 (very likely), how likely are you to recommend ABC Phones to friends or family? | F1: What is the main reason for your score? | G1: What is one thing we could do to improve your experience with us? | H1: Are you happy with the quality and performance of your device? | I1: Are you happy with the service and support provided by ABC Phones? | J1: Have you ever experienced a delay in your payment reflecting in your ABC account? | K1: Have you ever had difficulty getting assistance from ABC Phones customer support when needed? | L1: (If Yes) – Please describe the challenge you faced and how we can improve your experience. | M1: Have you experienced any battery-related issues with your MoPhones device? | N1: Have you used the MoPhones app (MoApp) to manage your account or make payments? | O1: Which communication channel do you prefer when contacting MoPhones for inquiries or support? | P1: Have you ever had your phone lock despite making a payment on time? | Q1: Any other Feedback?
A2: BzK4Q11 | B2: k4z1Y6 | C2: 45769.635 | D2: rec2FCxHhqXw6aKRU | E2: 6 | H2: Yes | I2: Yes | J2: Yes | K2: Yes | L2: Unlocking my phone | M2: No | N2: Yes, and I am satisfied with the MoApp | O2: MoPhones App | P2: Yes | Q2: N/A
A3: b59V45Z | B3: AY9GMk | C3: 45769.637 | D3: recQcLWbPcep18Wdw | E3: 10 | H3: Yes | I3: Yes | J3: No | K3: No | L3: Response team always on time | M3: No | N3: Yes, and I am satisfied with the MoApp | O3: Free SMS – 25044 | P3: No | Q3: Would like to upgrade once I'm done with this loan
A4: GxKvYKO | B4: eGz8Ek | C4: 45769.647 | D4: recei9UEU0e5F9HuG | E4: 5 | H4: No | I4: No | J4: No | K4: Yes | L4: I bought a Samsung A42 which has fingerprint lock that doesn't work since I bought it from ABC, I took it back and it's wasn't fixed.. Then the Phone has an on and Off network issues | M4: No | N4: Yes, and I am satisfied with the MoApp | O4: Phone Call – +254 728 444 442 or +254 709 924 404 | P4: Yes | Q4: Good service and efficient response
A5: A7KP49z | B5: LjOx7j | C5: 45769.653 | D5: recosDWAJvWzAKgLv | E5: 1 | H5: No | I5: No | J5: Yes | K5: Yes | L5: Delays | M5: Yes | N5: Yes, but I am not satisfied with the MoApp
A6: 81zo6pr | B6: 7YE0RR | C6: 45769.653 | D6: recTJng0Mj0dJP1kv | E6: 1 | H6: No | I6: No | J6: Yes | K6: Yes | L6: Not satisfied with my phone | M6: Yes | N6: Yes, but I am not satisfied with the MoApp | O6: MoPhones App | P6: Yes | Q6: Not satisfied with my phone
A7: xXjxR5J | B7: RQjeLp | C7: 45769.653 | D7: recPKFOtpkS0z9Kpp | E7: 10 | H7: Yes | I7: Yes | J7: No | K7: No | L7: . | M7: No | N7: Yes, and I am satisfied with the MoApp | O7: Phone Call – +254 728 444 442 or +254 709 924 404 | P7: No | Q7: .
A8: GxKvQ6L | B8: ljz2Mo | C8: 45769.653 | D8: rechy4Nf0Ihxrdy85 | E8: 10
A9: rjBykB2 | B9: k4zjvo | C9: 45769.654 | D9: recayIesPKGAMilkX | E9: 0
A10: 5B4KeaM | B10: k4zjZJ | C10: 45769.654 | D10: rec86PnPzgTEunR4Q | E10: 9 | H10: No | I10: No | J10: Yes | K10: Yes | L10: There is a lot to be | M10: No | N10: Yes, and I am satisfied with the MoApp | O10: MoPhones App | P10: Yes | Q10: None
A11: 5B4Kp16 | B11: rQY9pN | C11: 45769.656 | D11: recJKsUBTzHl4IGK3 | E11: 10 | H11: Yes | I11: Yes | J11: Yes | K11: No, I have never looked for customer care | L11: N/A | M11: No | N11: Yes, and I am satisfied with the MoApp | O11: Phone Call – +254 728 444 442 or +254 709 924 404 | P11: No | Q11: N/A
A12: eqDZYBO | B12: AY9RGD | C12: 45769.656 | D12: recUmt3DbYL0gb025 | E12: 10 | H12: Yes | I12: Yes | J12: No | K12: No | L12: None | M12: No | N12: Yes, and I am satisfied with the MoApp | O12: Reach Out via a Sales Agent | P12: No | Q12: None
A13: aQeNaYv | B13: yRD5Dg | C13: 45769.656 | D13: recVOllpG6mFoGtaV | E13: 8 | H13: No | I13: Yes | J13: No | K13: No | L13: Battery can't store charge I need a replaced of battery | M13: Yes | N13: Yes, and I am satisfied with the MoApp | O13: Phone Call – +254 728 444 442 or +254 709 924 404 | P13: No | Q13: Kindly exchange my battery
A14: dWNqK2d | B14: gVzV5M | C14: 45769.656 | D14: reciMIpVjO2lBzHt8 | E14: 7 | H14: Yes | I14: Yes | J14: Yes | K14: No | L14: Payment terms are harsh | M14: No | N14: No, I have never used it | O14: Phone Call – +254 728 444 442 or +254 709 924 404 | P14: Yes | Q14: You need to check on payment terms
A15: WOr9jYJ | B15: AY9RN0 | C15: 45769.656 | D15: receJwqtM49LS8gE8 | E15: 10 | H15: Yes | I15: Yes | J15: Yes | K15: No, I have never looked for customer care | L15: No | M15: No | N15: No, I have never used it | O15: Phone Call – +254 728 444 442 or +254 709 924 404 | P15: Yes | Q15: Am happy for your service
A16: zxNX1Q8 | B16: 4YO00O | C16: 45769.656 | D16: recB2N3ejw9jeBo4l | E16: 0 | H16: No | I16: No | J16: Yes | K16: Yes | L16: My phone is not working despite payment | M16: Yes | N16: Yes, and I am satisfied with the MoApp | O16: Phone Call – +254 728 444 442 or +254 709 924 404 | P16: Yes | Q16: My phone has a charging problem since
A17: jabDkpQ | B17: gVzPBK | C17: 45769.657 | D17: recK9QseqaimraXBE | E17: 8 | H17: Yes | I17: Yes | J17: Yes | K17: No | L17: Have a 24/7 customer care services | M17: Yes | N17: Yes, but I am not satisfied with the MoApp | O17: Phone Call – +254 728 444 442 or +254 709 924 404 | P17: No | Q17: No
A18: PdDjkDx | B18: gVz85l | C18: 45769.658 | D18: rectavMBbkg1rwXIl | E18: 10 | H18: Yes | I18: Yes | J18: No | K18: No
A19: MeDK74X | B19: 8YrbNl | C19: 45769.659 | D19: recu8gML0JT6Cd9ES | E19: 3 | H19: No | I19: No | J19: Yes | K19: Yes | M19: Yes | N19: Yes, but I am not satisfied with the MoApp | O19: MoPhones App | P19: No | Q19: Improve in your app
A20: vGrjKyl | B20: 4YOlvb | C20: 45769.659 | D20: recHDnVDRlfvts5dQ | E20: 6 | H20: Yes | I20: Yes | J20: No | K20: Yes | L20: MOPHONES | M20: Yes | N20: Yes, and I am satisfied with the MoApp | O20: Free SMS – 25044 | P20: No | Q20: Nome
A21: XxrlzDL | B21: Qq4NYg | C21: 45769.66 | D21: recvDdpWZLA2VCChR | E21: 10 | H21: Yes | I21: No | J21: No | K21: Yes | L21: Support center should work 24\7 | M21: No | N21: No, I have never used it | O21: Phone Call – +254 728 444 442 or +254 709 924 404 | P21: Yes | Q21: No
A22: zxNXL0q | B22: AY9M4N | C22: 45769.66 | D22: rec7AnOdegQgCwyT6 | E22: 8 | H22: Yes | I22: Yes | J22: Yes | K22: No | L22: Avoid delay while approving a grace period | M22: Yes | N22: Yes, and I am satisfied with the MoApp | O22: Free SMS – 25044 | P22: Yes | Q22: None
A23: Y5RDkx6 | B23: k4z8rZ | C23: 45769.66 | D23: recIZZtnG0LN1MpqF | E23: 9 | H23: Yes | I23: Yes | J23: Yes | K23: Yes | L23: You don't accept calls
A24: 7RblMyZ | B24: ljz8GB | C24: 45769.66 | D24: recAyJ8v8VJuecwtB | E24: 9 | H24: Yes | I24: Yes | J24: No | K24: No
A25: kd9av2R | B25: OZEx27 | C25: 45769.661 | D25: recjPY1G5I3fQxMOn | E25: 8 | H25: Yes | I25: Yes | J25: No | K25: No | L25: Non | M25: No | N25: Yes, but I am not satisfied with the MoApp | O25: Free SMS – 25044 | P25: No | Q25: No
A26: 2EB87Zg | B26: dozJVr | C26: 45769.662 | D26: rec4fZqbuemGwnwZF | E26: 10 | H26: Yes | I26: Yes | J26: No | K26: No | L26: No | M26: Yes | N26: No, I have never used it | O26: Phone Call – +254 728 444 442 or +254 709 924 404 | P26: No | Q26: No
A27: MeDKVb8 | B27: Jrovpz | C27: 45769.662 | D27: recl4egRn2rQH4mO0 | H27: Yes | I27: Yes
A28: Y5RD9G0 | B28: Jrov97 | C28: 45769.662 | D28: recQJWCGAZ7yuy0k7 | E28: 8 | H28: Yes | I28: Yes | J28: Yes | K28: No | L28: No
A29: 9qXG4Z4 | B29: GVbAez | C29: 45769.662 | D29: rec6r5JWy61FR24fB | E29: 9 | H29: Yes | I29: Yes | J29: No | K29: No
A30: xXjxvbv | B30: RQjqej | C30: 45769.662 | D30: recEx6e0qdGKb242p | E30: 10 | H30: Yes | I30: Yes | J30: No | K30: No | L30: No | M30: Yes | N30: Yes, and I am satisfied with the MoApp | O30: MoPhones App | P30: No | Q30: Had some challenges at the beginning but they were sorted.The only big problem I have with device is about battery.It doesn't last even 3 hours after full charge.
A31: Ek5z6ao | B31: 6YPEOk | C31: 45769.663 | D31: recCz1heG9HYapz1Z | E31: 10 | H31: Yes | I31: Yes | J31: Yes
A32: GxKvb5p | B32: JrovLR | C32: 45769.664 | D32: recqipYF4bAylKqe7 | E32: 6 | H32: Yes | I32: Yes | J32: No | K32: No, I have never looked for customer care | L32: 0 | M32: No | N32: Yes, and I am satisfied with the MoApp | O32: MoPhones App | P32: Yes | Q32: 0
A33: J9dKoXo | B33: 2YoGkD | C33: 45769.665 | D33: recbprJ3ndI6F0BhS | E33: 7 | H33: No | I33: Yes | J33: Yes | K33: Yes | L33: Someday I texted WhatsApp | M33: Yes | N33: Yes, and I am satisfied with the MoApp | O33: Reach Out via a Sales Agent | P33: No | Q33: NA
A34: yPNZ1pW | B34: gVz6Yd | C34: 45769.665 | D34: recO4cc15FMgzK9Jf | E34: 5 | H34: Yes | I34: No | J34: Yes | K34: Yes | L34: Weekends | M34: No | N34: No, I have never used it | O34: Reach Out via a Sales Agent | P34: Yes | Q34: Weekend
A35: jabDvGE | B35: NxP2RN | C35: 45769.665 | D35: recz6bPleTRitJUVS | E35: 3 | H35: Yes | I35: No | J35: Yes | K35: Yes | L35: I came to your shop with a complain about the phone battery bt bt instead of charging it, they gave me back the phone with the problem | M35: Yes | N35: No, I have never used it | O35: Phone Call – +254 728 444 442 or +254 709 924 404 | P35: Yes | Q35: No
A36: VLjENej | B36: gVz6z1 | C36: 45769.666 | D36: receqs5xvBzt3P9sN | E36: 8 | H36: Yes | I36: Yes | J36: No | K36: No | L36: have always been satisfied. | M36: No | N36: Yes, and I am satisfied with the MoApp | O36: Phone Call – +254 728 444 442 or +254 709 924 404 | P36: Yes | Q36: despite the challenge have had, am equally satisfied with your services.
A37: LZz1OB2 | B37: qqz1o7 | C37: 45769.666 | D37: rec9xhHoNXXxZVhm1 | E37: 6 | H37: Yes | I37: Yes | J37: No | K37: No | L37: T | M37: Yes | N37: Yes, but I am not satisfied with the MoApp | O37: Phone Call – +254 728 444 442 or +254 709 924 404 | P37: No | Q37: The MoApp should show the history of all transactions relating to a device payment.
A38: pbdxZrq | B38: BYeWY1 | C38: 45769.666 | D38: rect7DnuaYY5R6mKZ | E38: 8 | H38: Yes | I38: Yes | J38: No | K38: No | L38: I love ur phones | M38: No | N38: Yes, and I am satisfied with the MoApp | O38: Phone Call – +254 728 444 442 or +254 709 924 404 | P38: No | Q38: Goodservices viva!!
A39: Zjo5QEy | B39: 6YPE0A | C39: 45769.667 | D39: recLaXBaXTBTK6jWH | E39: 10 | H39: Yes | I39: Yes | J39: No | K39: No | L39: 😁 | M39: No | N39: No, I have never used it | O39: Phone Call – +254 728 444 442 or +254 709 924 404 | P39: Yes | Q39: 😎😮‍💨
A40: yPNZ71x | B40: 7YEkqL | C40: 45769.667 | D40: recJKLuwWfZr7TL15 | E40: 8 | H40: Yes | I40: Yes
...

Sheet Duplicates
A1: Submission ID | B1: Respondent ID | C1: Submitted at | D1: Loan Id | E1: Using a scale from 0 (not likely) to 10 (very likely), how likely are you to recommend ABC Phones to friends or family? | F1: What is the main reason for your score? | G1: What is one thing we could do to improve your experience with us? | H1: Are you happy with the quality and performance of your device? | I1: Are you happy with the service and support provided by ABC Phones? | J1: Have you ever experienced a delay in your payment reflecting in your ABC account? | K1: Have you ever had difficulty getting assistance from ABC Phones customer support when needed? | L1: (If Yes) – Please describe the challenge you faced and how we can improve your experience. | M1: Have you experienced any battery-related issues with your MoPhones device? | N1: Have you used the MoPhones app (MoApp) to manage your account or make payments? | O1: Which communication channel do you prefer when contacting MoPhones for inquiries or support? | P1: Have you ever had your phone lock despite making a payment on time? | Q1: Any other Feedback?
A2: eqDZYBO | B2: AY9RGD | C2: 45769.656 | D2: recUmt3DbYL0gb025 | E2: 10 | H2: Yes | I2: Yes | J2: No | K2: No | L2: None | M2: No | N2: Yes, and I am satisfied with the MoApp | O2: Reach Out via a Sales Agent | P2: No | Q2: None
A3: aQeNaYv | B3: yRD5Dg | C3: 45769.656 | D3: recVOllpG6mFoGtaV | E3: 8 | H3: No | I3: Yes | J3: No | K3: No | L3: Battery can't store charge I need a replaced of battery | M3: Yes | N3: Yes, and I am satisfied with the MoApp | O3: Phone Call – +254 728 444 442 or +254 709 924 404 | P3: No | Q3: Kindly exchange my battery
A4: jabDkpQ | B4: gVzPBK | C4: 45769.657 | D4: recK9QseqaimraXBE | E4: 8 | H4: Yes | I4: Yes | J4: Yes | K4: No | L4: Have a 24/7 customer care services | M4: Yes | N4: Yes, but I am not satisfied with the MoApp | O4: Phone Call – +254 728 444 442 or +254 709 924 404 | P4: No | Q4: No
A5: XxrlzDL | B5: Qq4NYg | C5: 45769.66 | D5: recvDdpWZLA2VCChR | E5: 10 | H5: Yes | I5: No | J5: No | K5: Yes | L5: Support center should work 24\7 | M5: No | N5: No, I have never used it | O5: Phone Call – +254 728 444 442 or +254 709 924 404 | P5: Yes | Q5: No
A6: 2EB87Zg | B6: dozJVr | C6: 45769.662 | D6: rec4fZqbuemGwnwZF | E6: 10 | H6: Yes | I6: Yes | J6: No | K6: No | L6: No | M6: Yes | N6: No, I have never used it | O6: Phone Call – +254 728 444 442 or +254 709 924 404 | P6: No | Q6: No
A7: Y5RD9G0 | B7: Jrov97 | C7: 45769.662 | D7: recQJWCGAZ7yuy0k7 | E7: 8 | H7: Yes | I7: Yes | J7: Yes | K7: No | L7: No
A8: xXjxvbv | B8: RQjqej | C8: 45769.662 | D8: recEx6e0qdGKb242p | E8: 10 | H8: Yes | I8: Yes | J8: No | K8: No | L8: No | M8: Yes | N8: Yes, and I am satisfied with the MoApp | O8: MoPhones App | P8: No | Q8: Had some challenges at the beginning but they were sorted.The only big problem I have with device is about battery.It doesn't last even 3 hours after full charge.
A9: Ek5z6ao | B9: 6YPEOk | C9: 45769.663 | D9: recCz1heG9HYapz1Z | E9: 10 | H9: Yes | I9: Yes | J9: Yes
A10: GxKvb5p | B10: JrovLR | C10: 45769.664 | D10: recqipYF4bAylKqe7 | E10: 6 | H10: Yes | I10: Yes | J10: No | K10: No, I have never looked for customer care | L10: 0 | M10: No | N10: Yes, and I am satisfied with the MoApp | O10: MoPhones App | P10: Yes | Q10: 0
A11: J9dKoXo | B11: 2YoGkD | C11: 45769.665 | D11: recbprJ3ndI6F0BhS | E11: 7 | H11: No | I11: Yes | J11: Yes | K11: Yes | L11: Someday I texted WhatsApp | M11: Yes | N11: Yes, and I am satisfied with the MoApp | O11: Reach Out via a Sales Agent | P11: No | Q11: NA
A12: Xxrl9Yd | B12: jrzV2R | C12: 45769.671 | D12: receZqSPKKw8UDIKZ | E12: 10 | H12: Yes | I12: Yes | J12: No | K12: No | L12: No | M12: No | N12: Yes, and I am satisfied with the MoApp | O12: Phone Call – +254 728 444 442 or +254 709 924 404 | P12: No | Q12: I will definitely refer someone
A13: GNVKNZ | B13: LNYObO | C13: 45769.671 | D13: recjLCHYg0W63oFyq | E13: 9 | H13: Yes | I13: Yes | J13: No | K13: No | L13: I have never encountered any problem | M13: No | N13: No, I have never used it | O13: Reach Out via a Sales Agent | P13: No | Q13: I really appreciate the sales lady for the good work she did and helping out when i was purchasing the device 👍
A14: 68eJ9jA | B14: oZzPM1 | C14: 45769.674 | D14: recnPnRd0SWb2mvlT | E14: 10 | H14: Yes | I14: Yes | J14: No | K14: No | L14: Referred a friend but didnt get my discount | M14: No | N14: Yes, and I am satisfied with the MoApp | O14: Phone Call – +254 728 444 442 or +254 709 924 404 | P14: No | Q14: No
A15: 81zoWbz | B15: M2V4Qp | C15: 45769.675 | D15: recyRMj9xxAynZxRG | E15: 1 | H15: Yes | I15: Yes
A16: yPNZGRd | B16: AY9g0D | C16: 45769.677 | D16: recz9P2LdiWAYmkfD | E16: 9 | H16: Yes | I16: Yes | J16: No | K16: No | L16: I have not experienced any challenge but you should adjust your payments to be done daily not weekly | M16: Yes | N16: Yes, but I am not satisfied with the MoApp | O16: Phone Call – +254 728 444 442 or +254 709 924 404 | P16: Yes | Q16: I suggest daily payments
A17: 44BXdQB | B17: 5YV7Rb | C17: 45769.679 | D17: reczlWsMPQNj2ZuLG | E17: 6 | H17: Yes | I17: No | J17: Yes | K17: Yes | L17: I had an issue whereby my device battery bulged causing the screen to break and when I took it for fixing with warranty it was never replaced I now use a phone which has a cracked screen and the on screen fingerprints is no longer functional. | M17: Yes | N17: Yes, and I am satisfied with the MoApp | O17: MoPhones App | P17: No | Q17: N/A
A18: VLjEy76 | B18: 7YEyJ9 | C18: 45769.679 | D18: recgC6NF6aU6ykuWP | E18: 10 | H18: Yes | I18: Yes | J18: Yes | K18: No | L18: No | M18: No | N18: Yes, and I am satisfied with the MoApp | O18: Free SMS – 25044 | P18: Yes | Q18: None
A19: xXjxB8k | B19: 4YOMPo | C19: 45769.68 | D19: rec0ITuqc7Hbmh5I0 | E19: 9 | H19: Yes | I19: Yes | J19: Yes | K19: No | L19: So far so good | M19: No | N19: Yes, and I am satisfied with the MoApp | O19: Phone Call – +254 728 444 442 or +254 709 924 404 | P19: No | Q19: Maybe due to cureent economic times the installmwnts couod be atleast 1300 or there aboout, plus also consedaration on not locking phone before pay days, the deffier from.one customer to the other, mine is on 7th
A20: NpD5y5G | B20: NxPjab | C20: 45769.68 | D20: recNzVJ7ttBMXABMd | E20: 4 | H20: No | I20: Yes | J20: No | K20: No, I have never looked for customer care | L20: My device at times has speaker issues | M20: Yes | N20: No, I have never used it | O20: Phone Call – +254 728 444 442 or +254 709 924 404 | P20: No | Q20: How do I use warranty coz my phone has speaker issue at times
A21: VLjEALJ | B21: PNr7g1 | C21: 45769.681 | D21: reckiVrQkFIioiJEJ | E21: 10 | H21: Yes | I21: Yes | J21: No | K21: No | L21: None | M21: Yes | N21: Yes, and I am satisfied with the MoApp | O21: Phone Call – +254 728 444 442 or +254 709 924 404 | P21: No | Q21: My battery is not last for long
A22: gDej1VN | B22: 5YVN9Q | C22: 45769.683 | D22: rec1I4Edrs4d5BdhW | E22: 10 | H22: Yes | I22: Yes | J22: No | K22: No | L22: None | M22: No | N22: No, I have never used it | O22: Phone Call – +254 728 444 442 or +254 709 924 404 | P22: No | Q22: None
A23: NpD5QGp | B23: 6YPqxJ | C23: 45769.683 | D23: rect5BpHLRHHJ1biS | E23: 4 | H23: Yes | I23: Yes
A24: PdDjePV | B24: 6YPq85 | C24: 45769.683 | D24: rec3F60HEZQdHj8kA | E24: 10 | H24: Yes | I24: Yes | J24: No | K24: No | L24: It's better keep up | M24: No | N24: Yes, and I am satisfied with the MoApp | O24: MoPhones App | P24: No | Q24: It's better
A25: PdDjWjB | B25: 1YRjvp | C25: 45769.684 | D25: recQqKMpvU6GUh8jS | E25: 8 | H25: Yes | I25: Yes | J25: Yes | K25: No | L25: I was going through a financial crisis and how to improve is just to work hard | M25: No | N25: Yes, and I am satisfied with the MoApp | O25: MoPhones App | P25: No | Q25: No
A26: aQeNPZW | B26: ljzp9X | C26: 45769.684 | D26: rec0CsNk3ewkMBGBu | E26: 3
A27: BzK4lWY | B27: OZER5a | C27: 45769.684 | D27: rec8l8Z3r5ZlxJgYm | E27: 5 | H27: Yes | I27: Yes | J27: Yes | K27: No | L27: Payment had not reflected | M27: Yes | N27: No, I have never used it | O27: Phone Call – +254 728 444 442 or +254 709 924 404 | P27: Yes | Q27: Offer some discounts once we pay on time
A28: rjBybV5 | B28: OZERrA | C28: 45769.686 | D28: recrmy7WSvZjq30aU | E28: 10 | H28: Yes | I28: Yes | J28: Yes | K28: No | L28: N/A | M28: No | N28: Yes, and I am satisfied with the MoApp | O28: Free SMS – 25044 | P28: No | Q28: N/A
A29: Ek5zeDX | B29: W6qyYk | C29: 45769.69 | D29: recF27j93eHkcruZo | E29: 8 | H29: Yes | I29: Yes | J29: No | K29: No, I have never looked for customer care | L29: None | M29: No | N29: No, I have never used it | O29: Phone Call – +254 728 444 442 or +254 709 924 404 | P29: No | Q29: Would recommend mo phones its a 10/10
A30: 68eJYe5 | B30: Qq4LLX | C30: 45769.691 | D30: recKGakMTzFkL8QST | E30: 5 | H30: No
A31: pbdxXlb | B31: dozreD | C31: 45769.692 | D31: recL6XUnkmp58e4Fz | E31: 9 | H31: Yes | I31: Yes | J31: No | K31: No | L31: . | M31: No | N31: Yes, and I am satisfied with the MoApp | O31: Phone Call – +254 728 444 442 or +254 709 924 404 | P31: No | Q31: I'll recommend this to anyone at anytime Then at the bottom of my screen there is this word "device beling to your organisation " can it be deleted
A32: QKM2pvA | B32: pNza4B | C32: 45769.692 | D32: recCEq4crXYGLkUFQ | E32: 10 | H32: Yes | I32: Yes | J32: No | K32: No | L32: Na | M32: No | N32: Yes, and I am satisfied with the MoApp | O32: MoPhones App | P32: No | Q32: N/A
A33: MeDK2R8 | B33: OZEvpg | C33: 45769.692 | D33: recYbbreaZ4DitlYy | E33: 6 | H33: Yes | I33: Yes | J33: Yes | K33: Yes | L33: Yes | M33: Yes | N33: Yes, and I am satisfied with the MoApp | O33: MoPhones App | P33: Yes | Q33: Yes
A34: GxKvV1e | B34: x1Z5Py | C34: 45769.692 | D34: recis4aVIpI8lbhMO | E34: 8 | H34: Yes | I34: Yes | J34: No | K34: No | L34: No | M34: Yes | N34: Yes, and I am satisfied with the MoApp | O34: MoPhones App | P34: No | Q34: No
A35: gDejVqM | B35: 6YPoaY | C35: 45769.694 | D35: recZNI80pG0AJlJib | E35: 10 | H35: Yes | I35: Yes | J35: No | K35: No | L35: Have | M35: Yes | N35: Yes, and I am satisfied with the MoApp | O35: Phone Call – +254 728 444 442 or +254 709 924 404 | P35: No | Q35: No
A36: 81zoDgA | B36: 6YPXjJ | C36: 45769.698 | D36: recA8DuV3yLD4bP7m | E36: 7 | H36: Yes | I36: Yes | J36: No | K36: No, I have never looked for customer care | L36: Not applicable | M36: Yes | N36: Yes, and I am satisfied with the MoApp | O36: Free SMS – 25044 | P36: No | Q36: Battery drains fast
A37: 2EB8d2M | B37: yb1Wy4 | C37: 45769.699 | D37: recZixuN8JQSPpLtb | E37: 10 | H37: Yes | I37: Yes | J37: No | K37: No | L37: No | M37: No | N37: Yes, and I am satisfied with the MoApp | O37: Phone Call – +254 728 444 442 or +254 709 924 404 | P37: No | Q37: Best services
A38: xXjxov9 | B38: gVzlvD | C38: 45769.7 | D38: recwdZCb5tboLX1i6 | E38: 5 | H38: No | I38: No | J38: Yes | K38: No | L38: My phone usually hangs,the camera has started fading I don't know y....yet has not finished even half a year.... | M38: Yes | N38: Yes, and I am satisfied with the MoApp | O38: MoPhones App | P38: No | Q38: Battery drains under 10 hrs
A39: yPNZaPp | B39: AY9okD | C39: 45769.707 | D39: recYdRr5oOw861Emd | E39: 10 | H39: Yes | I39: Yes | J39: Yes | K39: No, I have never looked for customer care
A40: PdDjJVb | B40: k4zDPe | C40: 45769.707 | D40: rec9TxaSWA6t0YEV0 | E40: 0 | H40: No | I40: No | J40: No | K40: Yes | L40: No phone picking | M40: No | N40: Yes, but I am not satisfied with the MoApp | O40: Self-Service USSD – *789*25044# | P40: Yes | Q40: I'm overcharged for a phone value now is too low interest
...
